Workbook

Sheet ExpiryTable
A1: Month | B1: Expiry
A2: Jan | B2: 45674
A3: Feb | B3: 45709
A4: Mar | B4: 45737
A5: Apr | B5: 45764
A6: May | B6: 45793
A7: Jun | B7: 45828
A8: Jul | B8: 45856
A9: Aug | B9: 45884
A10: Sep | B10: 45919
A11: Oct | B11: 45947
A12: Nov | B12: 45982
A13: Dec | B13: 46010
... A15: Feb | B15: 46073

Sheet Call
A1: Date | B1: Underlying (SPX Spot) | C1: ATM Strike | D1: FrontExp | E1: NextExp | F1: TargetDTE | G1: DTE_F = FrontExp - Date | H1: DTE_N = NextExp - Date | I1: Weighted_Front | J1: Weighted_N | K1: Check | L1: Front Call Ticker | M1: Last | N1: Bid | O1: Ask | P1: Mid=(Bid+Ask)/2 | Q1: Delta | R1: IV | S1: Next Call Ticker | T1: Last | U1: Bid | V1: Ask | W1: Mid=(Bid+Ask)/2 | X1: Delta | Y1: IV | Z1: IV_30D | AA1: IV_30D(call+put)/2 | AB1: RF_1M | AC1: RF_1M/100 | AD1: T(30/365) | AE1: Call delta | AF1: Put delta | AG1: Straddle delta
A2: 45659 | B2: 5868.55 | C2: 5870 | D2: 45674 | E2: 45709 | F2: 30 | G2: 15 | H2: 50 | I2: 0.57142857 | J2: 0.42857143 | K2: OK | L2: SPX 1/17/25 C5870 Index | M2: 73.29 | N2: 74.9 | O2: 76.7 | P2: 75.8 | Q2: #N/A N/A | R2: 14.31 | S2: SPX 2/21/25 C5870 Index | T2: 143.02 | U2: 140.2 | V2: 142.2 | W2: 141.2 | X2: #N/A N/A | Y2: 14.373 | Z2: =I2*R2+Y2*J2 -> 14.337 | AA2: 0.14406214 | AB2: 4.2912 | AC2: =AB2/100 -> 0.042912 | AD2: =30/365 -> 0.082191781 | AE2: =_xlfn.NORM.S.DIST((LN(B2/C2)+(AC2+0.5*(AA2)^2)*(30/365))/(AA2*SQRT(30/365)),TRUE) -> 0.53985409 | AF2: =AE2-1 -> -0.46014591 | AG2: =AE2+AF2 -> 0.079708175
A3: 45660 | B3: 5942.47 | C3: 5940 | D3: 45674 | E3: 45709 | F3: 30 | G3: 14 | H3: 49 | I3: 0.54285714 | J3: 0.45714286 | K3: OK | L3: SPX 1/17/25 C5940 Index | M3: 58.55 | N3: 60.7 | O3: 62.4 | P3: 61.55 | Q3: #N/A N/A | R3: 12.103 | S3: SPX 2/21/25 C5940 Index | T3: 130.73 | U3: 127.9 | V3: 129.7 | W3: 128.8 | X3: #N/A N/A | Y3: 13.127 | Z3: =I3*R3+Y3*J3 -> 12.571114 | AA3: 0.12756243 | AB3: 4.2626 | AC3: =AB3/100 -> 0.042626 | AD3: =30/365 -> 0.082191781 | AE3: =_xlfn.NORM.S.DIST((LN(B3/C3)+(AC3+0.5*(AA3)^2)*(30/365))/(AA3*SQRT(30/365)),TRUE) -> 0.54991777 | AF3: =AE3-1 -> -0.45008223 | AG3: =AE3+AF3 -> 0.099835537
A4: 45663 | B4: 5975.38 | C4: 5975 | D4: 45674 | E4: 45709 | F4: 30 | G4: 11 | H4: 46 | I4: 0.45714286 | J4: 0.54285714 | K4: OK | L4: SPX 1/17/25 C5975 Index | M4: 58.3 | N4: 59.6 | O4: 60.9 | P4: 60.25 | Q4: #N/A N/A | R4: 12.246 | S4: SPX 2/21/25 C5975 Index | T4: 126.1 | U4: 127.2 | V4: 128.7 | W4: 127.95 | X4: #N/A N/A | Y4: 12.896 | Z4: =I4*R4+Y4*J4 -> 12.598857 | AA4: 0.12818171 | AB4: 4.3106 | AC4: =AB4/100 -> 0.043106 | AD4: =30/365 -> 0.082191781 | AE4: =_xlfn.NORM.S.DIST((LN(B4/C4)+(AC4+0.5*(AA4)^2)*(30/365))/(AA4*SQRT(30/365)),TRUE) -> 0.54637808 | AF4: =AE4-1 -> -0.45362192 | AG4: =AE4+AF4 -> 0.09275615
A5: 45664 | B5: 5909.03 | C5: 5910 | D5: 45674 | E5: 45709 | F5: 30 | G5: 10 | H5: 45 | I5: 0.42857143 | J5: 0.57142857 | K5: OK | L5: SPX 1/17/25 C5910 Index | M5: 61.5 | N5: 59.3 | O5: 60.6 | P5: 59.95 | Q5: #N/A N/A | R5: 14.436 | S5: SPX 2/21/25 C5910 Index | T5: 141.67 | U5: 130.6 | V5: 132.2 | W5: 131.4 | X5: #N/A N/A | Y5: 14.319 | Z5: =I5*R5+Y5*J5 -> 14.369143 | AA5: 0.14519857 | AB5: 4.3024 | AC5: =AB5/100 -> 0.043024 | AD5: =30/365 -> 0.082191781 | AE5: =_xlfn.NORM.S.DIST((LN(B5/C5)+(AC5+0.5*(AA5)^2)*(30/365))/(AA5*SQRT(30/365)),TRUE) -> 0.54055033 | AF5: =AE5-1 -> -0.45944967 | AG5: =AE5+AF5 -> 0.081100665
A6: 45665 | B6: 5918.25 | C6: 5920 | D6: 45674 | E6: 45709 | F6: 30 | G6: 9 | H6: 44 | I6: 0.4 | J6: 0.6 | K6: OK | L6: SPX 1/17/25 C5920 Index | M6: 52.5 | N6: 51.1 | O6: 53.1 | P6: 52.1 | Q6: #N/A N/A | R6: 14.503 | S6: SPX 2/21/25 C5920 Index | T6: 121.43 | U6: 122.9 | V6: 125.9 | W6: 124.4 | X6: #N/A N/A | Y6: 14.171 | Z6: =I6*R6+Y6*J6 -> 14.3038 | AA6: 0.144391 | AB6: 4.2942 | AC6: =AB6/100 -> 0.042942 | AD6: =30/365 -> 0.082191781 | AE6: =_xlfn.NORM.S.DIST((LN(B6/C6)+(AC6+0.5*(AA6)^2)*(30/365))/(AA6*SQRT(30/365)),TRUE) -> 0.53935856 | AF6: =AE6-1 -> -0.46064144 | AG6: =AE6+AF6 -> 0.078717115
A7: 45667 | B7: 5827.04 | C7: 5825 | D7: 45674 | E7: 45709 | F7: 30 | G7: 7 | H7: 42 | I7: 0.34285714 | J7: 0.65714286 | K7: OK | L7: SPX 1/17/25 C5825 Index | M7: 51.7 | N7: 52.2 | O7: 53 | P7: 52.6 | Q7: #N/A N/A | R7: 16.298 | S7: SPX 2/21/25 C5825 Index | T7: 135.5 | U7: 131.3 | V7: 132.7 | W7: 132 | X7: #N/A N/A | Y7: 15.64 | Z7: =I7*R7+Y7*J7 -> 15.8656 | AA7: 0.15886814 | AB7: 4.283 | AC7: =AB7/100 -> 0.04283 | AD7: =30/365 -> 0.082191781 | AE7: =_xlfn.NORM.S.DIST((LN(B7/C7)+(AC7+0.5*(AA7)^2)*(30/365))/(AA7*SQRT(30/365)),TRUE) -> 0.54290352 | AF7: =AE7-1 -> -0.45709648 | AG7: =AE7+AF7 -> 0.085807035
A8: 45670 | B8: 5836.22 | C8: 5835 | D8: 45674 | E8: 45709 | F8: 30 | G8: 4 | H8: 39 | I8: 0.25714286 | J8: 0.74285714 | K8: OK | L8: SPX 1/17/25 C5835 Index | M8: 49.2 | N8: 52.5 | O8: 53.3 | P8: 52.9 | Q8: #N/A N/A | R8: 16.767 | S8: SPX 2/21/25 C5835 Index | T8: #N/A N/A | U8: 131.5 | V8: 133.1 | W8: 132.3 | X8: #N/A N/A | Y8: 15.195 | Z8: =I8*R8+Y8*J8 -> 15.599229 | AA8: 0.15632429 | AB8: 4.3055 | AC8: =AB8/100 -> 0.043055 | AD8: =30/365 -> 0.082191781 | AE8: =_xlfn.NORM.S.DIST((LN(B8/C8)+(AC8+0.5*(AA8)^2)*(30/365))/(AA8*SQRT(30/365)),TRUE) -> 0.54222229 | AF8: =AE8-1 -> -0.45777771 | AG8: =AE8+AF8 -> 0.084444585
A9: 45671 | B9: 5842.91 | C9: 5845 | D9: 45674 | E9: 45709 | F9: 30 | G9: 3 | H9: 38 | I9: 0.22857143 | J9: 0.77142857 | K9: OK | L9: SPX 1/17/25 C5845 Index | M9: 49.18 | N9: 47.9 | O9: 49 | P9: 48.45 | Q9: #N/A N/A | R9: 17.26 | S9: SPX 2/21/25 C5845 Index | T9: 110.7 | U9: 127.7 | V9: 129.9 | W9: 128.8 | X9: #N/A N/A | Y9: 15.042 | Z9: =I9*R9+Y9*J9 -> 15.548971 | AA9: 0.15803971 | AB9: 4.2998 | AC9: =AB9/100 -> 0.042998 | AD9: =30/365 -> 0.082191781 | AE9: =_xlfn.NORM.S.DIST((LN(B9/C9)+(AC9+0.5*(AA9)^2)*(30/365))/(AA9*SQRT(30/365)),TRUE) -> 0.53695339 | AF9: =AE9-1 -> -0.46304661 | AG9: =AE9+AF9 -> 0.073906781
A10: 45672 | B10: 5949.91 | C10: 5950 | D10: 45674 | E10: 45709 | F10: 30 | G10: 2 | H10: 37 | I10: 0.2 | J10: 0.8 | K10: OK | L10: SPX 1/17/25 C5950 Index | M10: 23.52 | N10: 22.7 | O10: 23.6 | P10: 23.15 | Q10: #N/A N/A | R10: 11.536 | S10: SPX 2/21/25 C5950 Index | T10: 107 | U10: 106.8 | V10: 108.4 | W10: 107.6 | X10: #N/A N/A | Y10: 12.836 | Z10: =I10*R10+Y10*J10 -> 12.576 | AA10: 0.127208 | AB10: 4.2917 | AC10: =AB10/100 -> 0.042917 | AD10: =30/365 -> 0.082191781 | AE10: =_xlfn.NORM.S.DIST((LN(B10/C10)+(AC10+0.5*(AA10)^2)*(30/365))/(AA10*SQRT(30/365)),TRUE) -> 0.54559624 | AF10: =AE10-1 -> -0.45440376 | AG10: =AE10+AF10 -> 0.091192477
A11: 45673 | B11: 5937.34 | C11: 5935 | D11: 45674 | E11: 45709 | F11: 30 | G11: 1 | H11: 36 | I11: 0.17142857 | J11: 0.82857143 | K11: OK | L11: SPX 1/17/25 C5935 Index | M11: 11.37 | N11: 11.4 | O11: 12.6 | P11: 12 | Q11: #N/A N/A | R11: 10.444 | S11: SPX 2/21/25 C5935 Index | T11: 113.8 | U11: 104 | V11: 106.1 | W11: 105.05 | X11: #N/A N/A | Y11: 13.009 | Z11: =I11*R11+Y11*J11 -> 12.569286 | AA11: 0.12544929 | AB11: 4.2963 | AC11: =AB11/100 -> 0.042963 | AD11: =30/365 -> 0.082191781 | AE11: =_xlfn.NORM.S.DIST((LN(B11/C11)+(AC11+0.5*(AA11)^2)*(30/365))/(AA11*SQRT(30/365)),TRUE) -> 0.55058005 | AF11: =AE11-1 -> -0.44941995 | AG11: =AE11+AF11 -> 0.10116011
A12: 45674 | B12: 5996.66 | C12: 5995 | D12: 45709 | E12: 45737 | F12: 30 | G12: 35 | H12: 63 | I12: 1 | J12: 0 | K12: OK | L12: SPX 2/21/25 C5995 Index | M12: 103.5 | N12: 103.4 | O12: 105.1 | P12: 104.25 | Q12: #N/A N/A | R12: 12.862 | S12: SPX 3/21/25 C5995 Index | T12: #N/A N/A | U12: 148.8 | V12: 151.1 | W12: 149.95 | X12: #N/A N/A | Y12: 13.145 | Z12: =I12*R12+Y12*J12 -> 12.862 | AA12: 0.129615 | AB12: 4.3004 | AC12: =AB12/100 -> 0.043004 | AD12: =30/365 -> 0.082191781 | AE12: =_xlfn.NORM.S.DIST((LN(B12/C12)+(AC12+0.5*(AA12)^2)*(30/365))/(AA12*SQRT(30/365)),TRUE) -> 0.54821365 | AF12: =AE12-1 -> -0.45178635 | AG12: =AE12+AF12 -> 0.096427307
A13: 45678 | B13: 6049.24 | C13: 6050 | D13: 45709 | E13: 45737 | F13: 30 | G13: 31 | H13: 59 | I13: 1 | J13: 0 | K13: OK | L13: SPX 2/21/25 C6050 Index | M13: 92.42 | N13: 94.6 | O13: 97.6 | P13: 96.1 | Q13: #N/A N/A | R13: 11.612 | S13: SPX 3/21/25 C6050 Index | T13: 136.1 | U13: 141 | V13: 143.7 | W13: 142.35 | X13: #N/A N/A | Y13: 12.125 | Z13: =I13*R13+Y13*J13 -> 11.612 | AA13: 0.11738 | AB13: 4.2998 | AC13: =AB13/100 -> 0.042998 | AD13: =30/365 -> 0.082191781 | AE13: =_xlfn.NORM.S.DIST((LN(B13/C13)+(AC13+0.5*(AA13)^2)*(30/365))/(AA13*SQRT(30/365)),TRUE) -> 0.54701048 | AF13: =AE13-1 -> -0.45298952 | AG13: =AE13+AF13 -> 0.094020964
A14: 45679 | B14: 6086.37 | C14: 6085 | D14: 45709 | E14: 45737 | F14: 30 | G14: 30 | H14: 58 | I14: 1 | J14: 0 | K14: OK | L14: SPX 2/21/25 C6085 Index | M14: 91.24 | N14: 89 | O14: 90.4 | P14: 89.7 | Q14: #N/A N/A | R14: 11.413 | S14: SPX 3/21/25 C6085 Index | T14: 144.64 | U14: 137.1 | V14: 138.3 | W14: 137.7 | X14: #N/A N/A | Y14: 12.1 | Z14: =I14*R14+Y14*J14 -> 11.413 | AA14: 0.11523 | AB14: 4.3095 | AC14: =AB14/100 -> 0.043095 | AD14: =30/365 -> 0.082191781 | AE14: =_xlfn.NORM.S.DIST((LN(B14/C14)+(AC14+0.5*(AA14)^2)*(30/365))/(AA14*SQRT(30/365)),TRUE) -> 0.55193518 | AF14: =AE14-1 -> -0.44806482 | AG14: =AE14+AF14 -> 0.10387036
A15: 45680 | B15: 6118.71 | C15: 6120 | D15: 45709 | E15: 45737 | F15: 30 | G15: 29 | H15: 57 | I15: 0.96428571 | J15: 0.035714286 | K15: OK | L15: SPX 2/21/25 C6120 Index | M15: 83.15 | N15: 82.5 | O15: 84.3 | P15: 83.4 | Q15: #N/A N/A | R15: 11.283 | S15: SPX 3/21/25 C6120 Index | T15: 133.2 | U15: 124.9 | V15: 138.4 | W15: 131.65 | X15: #N/A N/A | Y15: 11.988 | Z15: =I15*R15+Y15*J15 -> 11.308179 | AA15: 0.11435089 | AB15: 4.309 | AC15: =AB15/100 -> 0.04309 | AD15: =30/365 -> 0.082191781 | AE15: =_xlfn.NORM.S.DIST((LN(B15/C15)+(AC15+0.5*(AA15)^2)*(30/365))/(AA15*SQRT(30/365)),TRUE) -> 0.54696343 | AF15: =AE15-1 -> -0.45303657 | AG15: =AE15+AF15 -> 0.093926863
A16: 45681 | B16: 6101.24 | C16: 6100 | D16: 45709 | E16: 45737 | F16: 30 | G16: 28 | H16: 56 | I16: 0.92857143 | J16: 0.071428571 | K16: OK | L16: SPX 2/21/25 C6100 Index | M16: 82.39 | N16: 82.9 | O16: 84 | P16: 83.45 | Q16: #N/A N/A | R16: 11.35 | S16: SPX 3/21/25 C6100 Index | T16: 132.4 | U16: 131.7 | V16: 133 | W16: 132.35 | X16: #N/A N/A | Y16: 11.987 | Z16: =I16*R16+Y16*J16 -> 11.3955 | AA16: 0.11493 | AB16: 4.3187 | AC16: =AB16/100 -> 0.043187 | AD16: =30/365 -> 0.082191781 | AE16: =_xlfn.NORM.S.DIST((LN(B16/C16)+(AC16+0.5*(AA16)^2)*(30/365))/(AA16*SQRT(30/365)),TRUE) -> 0.55186425 | AF16: =AE16-1 -> -0.44813575 | AG16: =AE16+AF16 -> 0.10372851
A17: 45684 | B17: 6012.28 | C17: 6010 | D17: 45709 | E17: 45737 | F17: 30 | G17: 25 | H17: 53 | I17: 0.82142857 | J17: 0.17857143 | K17: OK | L17: SPX 2/21/25 C6010 Index | M17: 100.29 | N17: 99.7 | O17: 101.6 | P17: 100.65 | Q17: #N/A N/A | R17: 13.927 | S17: SPX 3/21/25 C6010 Index | T17: 149.5 | U17: 148.5 | V17: 150.3 | W17: 149.4 | X17: #N/A N/A | Y17: 13.841 | Z17: =I17*R17+Y17*J17 -> 13.911643 | AA17: 0.13904179 | AB17: 4.3233 | AC17: =AB17/100 -> 0.043233 | AD17: =30/365 -> 0.082191781 | AE17: =_xlfn.NORM.S.DIST((LN(B17/C17)+(AC17+0.5*(AA17)^2)*(30/365))/(AA17*SQRT(30/365)),TRUE) -> 0.54719936 | AF17: =AE17-1 -> -0.45280064 | AG17: =AE17+AF17 -> 0.094398713
A18: 45685 | B18: 6067.7 | C18: 6070 | D18: 45709 | E18: 45737 | F18: 30 | G18: 24 | H18: 52 | I18: 0.78571429 | J18: 0.21428571 | K18: OK | L18: SPX 2/21/25 C6070 Index | M18: 83.7 | N18: 80.1 | O18: 81.8 | P18: 80.95 | Q18: #N/A N/A | R18: 12.607 | S18: SPX 3/21/25 C6070 Index | T18: 131.1 | U18: 129.2 | V18: 130.7 | W18: 129.95 | X18: #N/A N/A | Y18: 12.847 | Z18: =I18*R18+Y18*J18 -> 12.658429 | AA18: 0.127045 | AB18: 4.3279 | AC18: =AB18/100 -> 0.043279 | AD18: =30/365 -> 0.082191781 | AE18: =_xlfn.NORM.S.DIST((LN(B18/C18)+(AC18+0.5*(AA18)^2)*(30/365))/(AA18*SQRT(30/365)),TRUE) -> 0.54199856 | AF18: =AE18-1 -> -0.45800144 | AG18: =AE18+AF18 -> 0.083997128
A19: 45686 | B19: 6039.31 | C19: 6040 | D19: 45709 | E19: 45737 | F19: 30 | G19: 23 | H19: 51 | I19: 0.75 | J19: 0.25 | K19: OK | L19: SPX 2/21/25 C6040 Index | M19: 87.9 | N19: 86.1 | O19: 90.5 | P19: 88.3 | Q19: #N/A N/A | R19: 12.91 | S19: SPX 3/21/25 C6040 Index | T19: 133.33 | U19: 136.4 | V19: 139.9 | W19: 138.15 | X19: #N/A N/A | Y19: 12.895 | Z19: =I19*R19+Y19*J19 -> 12.90625 | AA19: 0.13197125 | AB19: 4.3274 | AC19: =AB19/100 -> 0.043274 | AD19: =30/365 -> 0.082191781 | AE19: =_xlfn.NORM.S.DIST((LN(B19/C19)+(AC19+0.5*(AA19)^2)*(30/365))/(AA19*SQRT(30/365)),TRUE) -> 0.54375776 | AF19: =AE19-1 -> -0.45624224 | AG19: =AE19+AF19 -> 0.087515523
A20: 45687 | B20: 6071.17 | C20: 6070 | D20: 45709 | E20: 45737 | F20: 30 | G20: 22 | H20: 50 | I20: 0.71428571 | J20: 0.28571429 | K20: OK | L20: SPX 2/21/25 C6070 Index | M20: 81.2 | N20: 74.6 | O20: 80.1 | P20: 77.35 | Q20: #N/A N/A | R20: 12.291 | S20: SPX 3/21/25 C6070 Index | T20: 125 | U20: 126.1 | V20: 132.3 | W20: 129.2 | X20: #N/A N/A | Y20: 12.724 | Z20: =I20*R20+Y20*J20 -> 12.414714 | AA20: 0.12592214 | AB20: 4.3167 | AC20: =AB20/100 -> 0.043167 | AD20: =30/365 -> 0.082191781 | AE20: =_xlfn.NORM.S.DIST((LN(B20/C20)+(AC20+0.5*(AA20)^2)*(30/365))/(AA20*SQRT(30/365)),TRUE) -> 0.54841936 | AF20: =AE20-1 -> -0.45158064 | AG20: =AE20+AF20 -> 0.096838717
A21: 45688 | B21: 6040.53 | C21: 6040 | D21: 45709 | E21: 45737 | F21: 30 | G21: 21 | H21: 49 | I21: 0.67857143 | J21: 0.32142857 | K21: OK | L21: SPX 2/21/25 C6040 Index | M21: 81.02 | N21: 79.2 | O21: 81.2 | P21: 80.2 | Q21: #N/A N/A | R21: 13.331 | S21: SPX 3/21/25 C6040 Index | T21: 133.8 | U21: 130.5 | V21: 132.7 | W21: 131.6 | X21: #N/A N/A | Y21: 13.189 | Z21: =I21*R21+Y21*J21 -> 13.285357 | AA21: 0.13419786 | AB21: 4.283 | AC21: =AB21/100 -> 0.04283 | AD21: =30/365 -> 0.082191781 | AE21: =_xlfn.NORM.S.DIST((LN(B21/C21)+(AC21+0.5*(AA21)^2)*(30/365))/(AA21*SQRT(30/365)),TRUE) -> 0.54499122 | AF21: =AE21-1 -> -0.45500878 | AG21: =AE21+AF21 -> 0.089982442
A22: 45691 | B22: 5994.57 | C22: 5995 | D22: 45709 | E22: 45737 | F22: 30 | G22: 18 | H22: 46 | I22: 0.57142857 | J22: 0.42857143 | K22: OK | L22: SPX 2/21/25 C5995 Index | M22: 86.2 | N22: 103 | O22: 105.3 | P22: 104.15 | Q22: #N/A N/A | R22: 14.652 | S22: SPX 3/21/25 C5995 Index | T22: 142 | U22: 155.4 | V22: 157.6 | W22: 156.5 | X22: #N/A N/A | Y22: 14.118 | Z22: =I22*R22+Y22*J22 -> 14.423143 | AA22: 0.14871929 | AB22: 4.3157 | AC22: =AB22/100 -> 0.043157 | AD22: =30/365 -> 0.082191781 | AE22: =_xlfn.NORM.S.DIST((LN(B22/C22)+(AC22+0.5*(AA22)^2)*(30/365))/(AA22*SQRT(30/365)),TRUE) -> 0.54095148 | AF22: =AE22-1 -> -0.45904852 | AG22: =AE22+AF22 -> 0.081902967
A23: 45692 | B23: 6037.88 | C23: 6040 | D23: 45709 | E23: 45737 | F23: 30 | G23: 17 | H23: 45 | I23: 0.53571429 | J23: 0.46428571 | K23: OK | L23: SPX 2/21/25 C6040 Index | M23: 67.36 | N23: 63.8 | O23: 65.5 | P23: 64.65 | Q23: #N/A N/A | R23: 13.31 | S23: SPX 3/21/25 C6040 Index | T23: 127.29 | U23: 117 | V23: 118.5 | W23: 117.75 | X23: #N/A N/A | Y23: 13.315 | Z23: =I23*R23+Y23*J23 -> 13.312321 | AA23: 0.13462089 | AB23: 4.3075 | AC23: =AB23/100 -> 0.043075 | AD23: =30/365 -> 0.082191781 | AE23: =_xlfn.NORM.S.DIST((LN(B23/C23)+(AC23+0.5*(AA23)^2)*(30/365))/(AA23*SQRT(30/365)),TRUE) -> 0.54059573 | AF23: =AE23-1 -> -0.45940427 | AG23: =AE23+AF23 -> 0.08119145
A24: 45693 | B24: 6061.48 | C24: 6060 | D24: 45709 | E24: 45737 | F24: 30 | G24: 16 | H24: 44 | I24: 0.5 | J24: 0.5 | K24: OK | L24: SPX 2/21/25 C6060 Index | M24: 66.5 | N24: 68.2 | O24: 69.6 | P24: 68.9 | Q24: #N/A N/A | R24: 12.341 | S24: SPX 3/21/25 C6060 Index | T24: 118.2 | U24: 123.7 | V24: 125.1 | W24: 124.4 | X24: #N/A N/A | Y24: 12.752 | Z24: =I24*R24+Y24*J24 -> 12.5465 | AA24: 0.126805 | AB24: 4.2942 | AC24: =AB24/100 -> 0.042942 | AD24: =30/365 -> 0.082191781 | AE24: =_xlfn.NORM.S.DIST((LN(B24/C24)+(AC24+0.5*(AA24)^2)*(30/365))/(AA24*SQRT(30/365)),TRUE) -> 0.54854291 | AF24: =AE24-1 -> -0.45145709 | AG24: =AE24+AF24 -> 0.097085828
... A42: 45720 | B42: 5778.15 | C42: 5780 | D42: 45737 | E42: 45764 | F42: 30 | G42: 17 | H42: 44 | I42: 0.51851852 | J42: 0.48148148 | K42: OK | L42: SPX 3/21/25 C5780 Index | M42: 124.5 | N42: 130.3 | O42: 131.8 | P42: 131.05 | Q42: #N/A N/A | R42: 20.397 | S42: SPX 4/17/25 C5780 Index | T42: 184 | U42: 184.1 | V42: 186.3 | W42: 185.2 | X42: #N/A N/A | Y42: 18.267 | Z42: =I42*R42+Y42*J42 -> 19.371444 | AA42: 0.19487907 | AB42: 4.3177 | AC42: =AB42/100 -> 0.043177 | AD42: =30/365 -> 0.082191781 | AE42: =_xlfn.NORM.S.DIST((LN(B42/C42)+(AC42+0.5*(AA42)^2)*(30/365))/(AA42*SQRT(30/365)),TRUE) -> 0.53415709 | AF42: =AE42-1 -> -0.46584291 | AG42: =AE42+AF42 -> 0.068314175
A43: 45721 | B43: 5842.63 | C43: 5845 | D43: 45737 | E43: 45764 | F43: 30 | G43: 16 | H43: 43 | I43: 0.48148148 | J43: 0.51851852 | K43: OK | L43: SPX 3/21/25 C5845 Index | M43: 99 | N43: 97.4 | O43: 99.5 | P43: 98.45 | Q43: #N/A N/A | R43: 19.536 | S43: SPX 4/17/25 C5845 Index | T43: #N/A N/A | U43: 149.2 | V43: 152.1 | W43: 150.65 | X43: #N/A N/A | Y43: 17.212 | Z43: =I43*R43+Y43*J43 -> 18.330963 | AA43: 0.18432185 | AB43: 4.3044 | AC43: =AB43/100 -> 0.043044 | AD43: =30/365 -> 0.082191781 | AE43: =_xlfn.NORM.S.DIST((LN(B43/C43)+(AC43+0.5*(AA43)^2)*(30/365))/(AA43*SQRT(30/365)),TRUE) -> 0.53414633 | AF43: =AE43-1 -> -0.46585367 | AG43: =AE43+AF43 -> 0.068292661
A44: 45722 | B44: 5738.52 | C44: 5740 | D44: 45737 | E44: 45764 | F44: 30 | G44: 15 | H44: 42 | I44: 0.44444444 | J44: 0.55555556 | K44: OK | L44: SPX 3/21/25 C5740 Index | M44: 117 | N44: 119.1 | O44: 121.2 | P44: 120.15 | Q44: #N/A N/A | R44: 23.106 | S44: SPX 4/17/25 C5740 Index | T44: 169.8 | U44: 176.2 | V44: 178.4 | W44: 177.3 | X44: #N/A N/A | Y44: 19.884 | Z44: =I44*R44+Y44*J44 -> 21.316 | AA44: 0.21380444 | AB44: 4.3014 | AC44: =AB44/100 -> 0.043014 | AD44: =30/365 -> 0.082191781 | AE44: =_xlfn.NORM.S.DIST((LN(B44/C44)+(AC44+0.5*(AA44)^2)*(30/365))/(AA44*SQRT(30/365)),TRUE) -> 0.53351889 | AF44: =AE44-1 -> -0.46648111 | AG44: =AE44+AF44 -> 0.06703779
A45: 45723 | B45: 5770.2 | C45: 5770 | D45: 45737 | E45: 45764 | F45: 30 | G45: 14 | H45: 41 | I45: 0.40740741 | J45: 0.59259259 | K45: OK | L45: SPX 3/21/25 C5770 Index | M45: 97 | N45: 96 | O45: 97.5 | P45: 96.75 | Q45: #N/A N/A | R45: 21.178 | S45: SPX 4/17/25 C5770 Index | T45: 150.34 | U45: 153.4 | V45: 158 | W45: 155.7 | X45: #N/A N/A | Y45: 18.626 | Z45: =I45*R45+Y45*J45 -> 19.665704 | AA45: 0.19796278 | AB45: 4.2856 | AC45: =AB45/100 -> 0.042856 | AD45: =30/365 -> 0.082191781 | AE45: =_xlfn.NORM.S.DIST((LN(B45/C45)+(AC45+0.5*(AA45)^2)*(30/365))/(AA45*SQRT(30/365)),TRUE) -> 0.53627443 | AF45: =AE45-1 -> -0.46372557 | AG45: =AE45+AF45 -> 0.072548865
A46: 45726 | B46: 5614.56 | C46: 5615 | D46: 45737 | E46: 45764 | F46: 30 | G46: 11 | H46: 38 | I46: 0.2962963 | J46: 0.7037037 | K46: OK | L46: SPX 3/21/25 C5615 Index | M46: 104 | N46: 112.1 | O46: 114.2 | P46: 113.15 | Q46: #N/A N/A | R46: 25.489 | S46: SPX 4/17/25 C5615 Index | T46: 177.1 | U46: 177.2 | V46: 180 | W46: 178.6 | X46: #N/A N/A | Y46: 21.942 | Z46: =I46*R46+Y46*J46 -> 22.992963 | AA46: 0.22893074 | AB46: 4.2953 | AC46: =AB46/100 -> 0.042953 | AD46: =30/365 -> 0.082191781 | AE46: =_xlfn.NORM.S.DIST((LN(B46/C46)+(AC46+0.5*(AA46)^2)*(30/365))/(AA46*SQRT(30/365)),TRUE) -> 0.53403326 | AF46: =AE46-1 -> -0.46596674 | AG46: =AE46+AF46 -> 0.068066514
A47: 45727 | B47: 5572.07 | C47: 5570 | D47: 45737 | E47: 45764 | F47: 30 | G47: 10 | H47: 37 | I47: 0.25925926 | J47: 0.74074074 | K47: OK | L47: SPX 3/21/25 C5570 Index | M47: 118.99 | N47: 102.6 | O47: 104.5 | P47: 103.55 | Q47: #N/A N/A | R47: 25.683 | S47: SPX 4/17/25 C5570 Index | T47: 183.37 | U47: 172.3 | V47: 174.6 | W47: 173.45 | X47: #N/A N/A | Y47: 22.181 | Z47: =I47*R47+Y47*J47 -> 23.088926 | AA47: 0.23091056 | AB47: 4.2973 | AC47: =AB47/100 -> 0.042973 | AD47: =30/365 -> 0.082191781 | AE47: =_xlfn.NORM.S.DIST((LN(B47/C47)+(AC47+0.5*(AA47)^2)*(30/365))/(AA47*SQRT(30/365)),TRUE) -> 0.53667746 | AF47: =AE47-1 -> -0.46332254 | AG47: =AE47+AF47 -> 0.073354914
A48: 45728 | B48: 5599.3 | C48: 5600 | D48: 45737 | E48: 45764 | F48: 30 | G48: 9 | H48: 36 | I48: 0.22222222 | J48: 0.77777778 | K48: OK | L48: SPX 3/21/25 C5600 Index | M48: 83 | N48: 81.6 | O48: 83.3 | P48: 82.45 | Q48: #N/A N/A | R48: 22.739 | S48: SPX 4/17/25 C5600 Index | T48: 154 | U48: 152.7 | V48: 154.8 | W48: 153.75 | X48: #N/A N/A | Y48: 20.288 | Z48: =I48*R48+Y48*J48 -> 20.832667 | AA48: 0.20916611 | AB48: 4.2764 | AC48: =AB48/100 -> 0.042764 | AD48: =30/365 -> 0.082191781 | AE48: =_xlfn.NORM.S.DIST((LN(B48/C48)+(AC48+0.5*(AA48)^2)*(30/365))/(AA48*SQRT(30/365)),TRUE) -> 0.53447044 | AF48: =AE48-1 -> -0.46552956 | AG48: =AE48+AF48 -> 0.068940873
A49: 45729 | B49: 5521.52 | C49: 5520 | D49: 45737 | E49: 45764 | F49: 30 | G49: 8 | H49: 35 | I49: 0.18518519 | J49: 0.81481481 | K49: OK | L49: SPX 3/21/25 C5520 Index | M49: 87 | N49: 87.8 | O49: 89 | P49: 88.4 | Q49: #N/A N/A | R49: 23.371 | S49: SPX 4/17/25 C5520 Index | T49: 165.23 | U49: 165.6 | V49: 167.6 | W49: 166.6 | X49: #N/A N/A | Y49: 21.288 | Z49: =I49*R49+Y49*J49 -> 21.673741 | AA49: 0.21773444 | AB49: 4.281 | AC49: =AB49/100 -> 0.04281 | AD49: =30/365 -> 0.082191781 | AE49: =_xlfn.NORM.S.DIST((LN(B49/C49)+(AC49+0.5*(AA49)^2)*(30/365))/(AA49*SQRT(30/365)),TRUE) -> 0.53664696 | AF49: =AE49-1 -> -0.46335304 | AG49: =AE49+AF49 -> 0.073293917
A50: 45730 | B50: 5638.94 | C50: 5640 | D50: 45737 | E50: 45764 | F50: 30 | G50: 7 | H50: 34 | I50: 0.14814815 | J50: 0.85185185 | K50: OK | L50: SPX 3/21/25 C5640 Index | M50: 55.4 | N50: 55.1 | O50: 56.6 | P50: 55.85 | Q50: #N/A N/A | R50: 19.715 | S50: SPX 4/17/25 C5640 Index | T50: 137.8 | U50: 131 | V50: 133.5 | W50: 132.25 | X50: #N/A N/A | Y50: 18.547 | Z50: =I50*R50+Y50*J50 -> 18.720037 | AA50: 0.18848389 | AB50: 4.2856 | AC50: =AB50/100 -> 0.042856 | AD50: =30/365 -> 0.082191781 | AE50: =_xlfn.NORM.S.DIST((LN(B50/C50)+(AC50+0.5*(AA50)^2)*(30/365))/(AA50*SQRT(30/365)),TRUE) -> 0.53534997 | AF50: =AE50-1 -> -0.46465003 | AG50: =AE50+AF50 -> 0.070699948
A51: 45733 | B51: 5675.12 | C51: 5675 | D51: 45737 | E51: 45764 | F51: 30 | G51: 4 | H51: 31 | I51: 0.037037037 | J51: 0.96296296 | K51: OK | L51: SPX 3/21/25 C5675 Index | M51: 50.57 | N51: 51.3 | O51: 52.5 | P51: 51.9 | Q51: #N/A N/A | R51: 17.791 | S51: SPX 4/17/25 C5675 Index | T51: 140.03 | U51: 129.9 | V51: 131.7 | W51: 130.8 | X51: #N/A N/A | Y51: 17.511 | Z51: =I51*R51+Y51*J51 -> 17.52137 | AA51: 0.17533093 | AB51: 4.3029 | AC51: =AB51/100 -> 0.043029 | AD51: =30/365 -> 0.082191781 | AE51: =_xlfn.NORM.S.DIST((LN(B51/C51)+(AC51+0.5*(AA51)^2)*(30/365))/(AA51*SQRT(30/365)),TRUE) -> 0.53820482 | AF51: =AE51-1 -> -0.46179518 | AG51: =AE51+AF51 -> 0.07640964
A52: 45734 | B52: 5614.66 | C52: 5615 | D52: 45737 | E52: 45764 | F52: 30 | G52: 3 | H52: 30 | I52: 0 | J52: 1 | K52: OK | L52: SPX 3/21/25 C5615 Index | M52: 51.61 | N52: 48.1 | O52: 49.2 | P52: 48.65 | Q52: #N/A N/A | R52: 20.013 | S52: SPX 4/17/25 C5615 Index | T52: 134.73 | U52: 133.2 | V52: 134.9 | W52: 134.05 | X52: #N/A N/A | Y52: 18.692 | Z52: =I52*R52+Y52*J52 -> 18.692 | AA52: 0.18795 | AB52: 4.2973 | AC52: =AB52/100 -> 0.042973 | AD52: =30/365 -> 0.082191781 | AE52: =_xlfn.NORM.S.DIST((LN(B52/C52)+(AC52+0.5*(AA52)^2)*(30/365))/(AA52*SQRT(30/365)),TRUE) -> 0.5363996 | AF52: =AE52-1 -> -0.4636004 | AG52: =AE52+AF52 -> 0.072799197
A53: 45735 | B53: 5675.29 | C53: 5675 | D53: 45737 | E53: 45764 | F53: 30 | G53: 2 | H53: 29 | I53: 0 | J53: 1 | K53: OK | L53: SPX 3/21/25 C5675 Index | M53: 35.12 | N53: 31.8 | O53: 32.9 | P53: 32.35 | Q53: #N/A N/A | R53: 16.597 | S53: SPX 4/17/25 C5675 Index | T53: 122.86 | U53: 121.8 | V53: 123.9 | W53: 122.85 | X53: #N/A N/A | Y53: 17.229 | Z53: =I53*R53+Y53*J53 -> 17.229 | AA53: 0.172765 | AB53: 4.2917 | AC53: =AB53/100 -> 0.042917 | AD53: =30/365 -> 0.082191781 | AE53: =_xlfn.NORM.S.DIST((LN(B53/C53)+(AC53+0.5*(AA53)^2)*(30/365))/(AA53*SQRT(30/365)),TRUE) -> 0.53864255 | AF53: =AE53-1 -> -0.46135745 | AG53: =AE53+AF53 -> 0.07728509
A54: 45736 | B54: 5662.89 | C54: 5665 | D54: 45737 | E54: 45764 | F54: 30 | G54: 1 | H54: 28 | I54: 0 | J54: 1 | K54: OK | L54: SPX 3/21/25 C5665 Index | M54: 17.27 | N54: 16.4 | O54: 17.3 | P54: 16.85 | Q54: #N/A N/A | R54: 13.801 | S54: SPX 4/17/25 C5665 Index | T54: 124.8 | U54: 117.7 | V54: 119.3 | W54: 118.5 | X54: #N/A N/A | Y54: 17.188 | Z54: =I54*R54+Y54*J54 -> 17.188 | AA54: 0.17236 | AB54: 4.2861 | AC54: =AB54/100 -> 0.042861 | AD54: =30/365 -> 0.082191781 | AE54: =_xlfn.NORM.S.DIST((LN(B54/C54)+(AC54+0.5*(AA54)^2)*(30/365))/(AA54*SQRT(30/365)),TRUE) -> 0.53524443 | AF54: =AE54-1 -> -0.46475557 | AG54: =AE54+AF54 -> 0.070488866
A55: 45737 | B55: 5667.56 | C55: 5670 | D55: 45764 | E55: 45793 | F55: 30 | G55: 27 | H55: 56 | I55: 0.89655172 | J55: 0.10344828 | K55: OK | L55: SPX 4/17/25 C5670 Index | M55: 112.3 | N55: 111.8 | O55: 113.4 | P55: 112.6 | Q55: #N/A N/A | R55: 16.863 | S55: SPX 5/16/25 C5670 Index | T55: #N/A N/A | U55: 161.5 | V55: 163.1 | W55: 162.3 | X55: #N/A N/A | Y55: 16.475 | Z55: =I55*R55+Y55*J55 -> 16.822862 | AA55: 0.16874603 | AB55: 4.2753 | AC55: =AB55/100 -> 0.042753 | AD55: =30/365 -> 0.082191781 | AE55: =_xlfn.NORM.S.DIST((LN(B55/C55)+(AC55+0.5*(AA55)^2)*(30/365))/(AA55*SQRT(30/365)),TRUE) -> 0.53503266 | AF55: =AE55-1 -> -0.46496734 | AG55: =AE55+AF55 -> 0.070065322
A56: 45740 | B56: 5767.57 | C56: 5770 | D56: 45764 | E56: 45793 | F56: 30 | G56: 24 | H56: 53 | I56: 0.79310345 | J56: 0.20689655 | K56: OK | L56: SPX 4/17/25 C5770 Index | M56: 99.15 | N56: 94.5 | O56: 95.8 | P56: 95.15 | Q56: #N/A N/A | R56: 14.873 | S56: SPX 5/16/25 C5770 Index | T56: 149.91 | U56: 143.7 | V56: 145.2 | W56: 144.45 | X56: #N/A N/A | Y56: 14.876 | Z56: =I56*R56+Y56*J56 -> 14.873621 | AA56: 0.14914379 | AB56: 4.2825 | AC56: =AB56/100 -> 0.042825 | AD56: =30/365 -> 0.082191781 | AE56: =_xlfn.NORM.S.DIST((LN(B56/C56)+(AC56+0.5*(AA56)^2)*(30/365))/(AA56*SQRT(30/365)),TRUE) -> 0.53738496 | AF56: =AE56-1 -> -0.46261504 | AG56: =AE56+AF56 -> 0.07476993
A57: 45741 | B57: 5776.65 | C57: 5775 | D57: 45764 | E57: 45793 | F57: 30 | G57: 23 | H57: 52 | I57: 0.75862069 | J57: 0.24137931 | K57: OK | L57: SPX 4/17/25 C5775 Index | M57: 93.87 | N57: 98.6 | O57: 99.8 | P57: 99.2 | Q57: #N/A N/A | R57: 14.62 | S57: SPX 5/16/25 C5775 Index | T57: 139.6 | U57: 150 | V57: 151.5 | W57: 150.75 | X57: #N/A N/A | Y57: 14.821 | Z57: =I57*R57+Y57*J57 -> 14.668517 | AA57: 0.14754897 | AB57: 4.2896 | AC57: =AB57/100 -> 0.042896 | AD57: =30/365 -> 0.082191781 | AE57: =_xlfn.NORM.S.DIST((LN(B57/C57)+(AC57+0.5*(AA57)^2)*(30/365))/(AA57*SQRT(30/365)),TRUE) -> 0.54429165 | AF57: =AE57-1 -> -0.45570835 | AG57: =AE57+AF57 -> 0.088583302
...

Sheet Put
A1: Date | B1: Underlying (SPX Spot) | C1: ATM Strike | D1: FrontExp | E1: NextExp | F1: TargetDTE | G1: DTE_F = FrontExp - Date | H1: DTE_N = NextExp - Date | I1: Weighted_Front | J1: Weighted_N | K1: Check | L1: Front Call Ticker | M1: Last | N1: Bid | O1: Ask | P1: Mid=(Bid+Ask)/2 | Q1: Delta | R1: IV | S1: Next Call Ticker | T1: Last | U1: Bid | V1: Ask | W1: Mid=(Bid+Ask)/2 | X1: Delta | Y1: IV | Z1: IV_30D | AA1: IV_30D(call+put)/2
A2: 45659 | B2: 5868.55 | C2: 5870 | D2: 45674 | E2: 45709 | F2: 30 | G2: 15 | H2: 50 | I2: 0.57142857 | J2: 0.42857143 | K2: OK | L2: SPX 1/17/25 P5870 Index | M2: 62.5 | N2: 62.3 | O2: 64.2 | P2: 63.25 | Q2: #N/A N/A | R2: 14.37 | S2: SPX 2/21/25 P5870 Index | T2: 107.08 | U2: 106.9 | V2: 109.1 | W2: 108 | X2: #N/A N/A | Y2: 14.616 | Z2: =I2*R2+Y2*J2 -> 14.475429 | AA2: 0.14406214
A3: 45660 | B3: 5942.47 | C3: 5940 | D3: 45674 | E3: 45709 | F3: 30 | G3: P | H3: 49 | I3: 0.54285714 | J3: 0.45714286 | K3: OK | L3: SPX 1/17/25 P5940 Index | M3: 52.1 | N3: 53.1 | O3: 54.8 | P3: 53.95 | Q3: #N/A N/A | R3: 12.444 | S3: SPX 2/21/25 P5940 Index | T3: 98.67 | U3: 99.4 | V3: 101.2 | W3: 100.3 | X3: #N/A N/A | Y3: 13.532 | Z3: =I3*R3+Y3*J3 -> 12.941371 | AA3: 0.12756243
A4: 45663 | B4: 5975.38 | C4: 5975 | D4: 45674 | E4: 45709 | F4: 30 | G4: 11 | H4: 46 | I4: 0.45714286 | J4: 0.54285714 | K4: OK | L4: SPX 1/17/25 P5975 Index | M4: 49.54 | N4: 44.2 | O4: 45.6 | P4: 44.9 | Q4: #N/A N/A | R4: 12.683 | S4: SPX 2/21/25 P5975 Index | T4: 96.59 | U4: 91.1 | V4: 92.6 | W4: 91.85 | X4: #N/A N/A | Y4: 13.336 | Z4: =I4*R4+Y4*J4 -> 13.037486 | AA4: 0.12818171
A5: 45664 | B5: 5909.03 | C5: 5910 | D5: 45674 | E5: 45709 | F5: 30 | G5: 10 | H5: 45 | I5: 0.42857143 | J5: 0.57142857 | K5: OK | L5: SPX 1/17/25 P5910 Index | M5: 51.5 | N5: 52.5 | O5: 53.9 | P5: 53.2 | Q5: #N/A N/A | R5: 14.702 | S5: SPX 2/21/25 P5910 Index | T5: 95.71 | U5: 103.3 | V5: 104.9 | W5: 104.1 | X5: #N/A N/A | Y5: 14.647 | Z5: =I5*R5+Y5*J5 -> 14.670571 | AA5: 0.14519857
A6: 45665 | B6: 5918.25 | C6: 5920 | D6: 45674 | E6: 45709 | F6: 30 | G6: 9 | H6: 44 | I6: 0.4 | J6: 0.6 | K6: OK | L6: SPX 1/17/25 P5920 Index | M6: 50.78 | N6: 52.5 | O6: 54.6 | P6: 53.55 | Q6: #N/A N/A | R6: 14.647 | S6: SPX 2/21/25 P5920 Index | T6: 108.93 | U6: 104.5 | V6: 107.5 | W6: 106 | X6: #N/A N/A | Y6: 14.526 | Z6: =I6*R6+Y6*J6 -> 14.5744 | AA6: 0.144391
A7: 45667 | B7: 5827.04 | C7: 5825 | D7: 45674 | E7: 45709 | F7: 30 | G7: 7 | H7: 42 | I7: 0.34285714 | J7: 0.65714286 | K7: OK | L7: SPX 1/17/25 P5825 Index | M7: 50.23 | N7: 50.9 | O7: 51.7 | P7: 51.3 | Q7: #N/A N/A | R7: 15.956 | S7: SPX 2/21/25 P5825 Index | T7: 107 | U7: 110.4 | V7: 111.9 | W7: 111.15 | X7: #N/A N/A | Y7: 15.883 | Z7: =I7*R7+Y7*J7 -> 15.908029 | AA7: 0.15886814
A8: 45670 | B8: 5836.22 | C8: 5835 | D8: 45674 | E8: 45709 | F8: 30 | G8: 4 | H8: 39 | I8: 0.25714286 | J8: 0.74285714 | K8: OK | L8: SPX 1/17/25 P5835 Index | M8: 44.3 | N8: 41.1 | O8: 41.7 | P8: 41.4 | Q8: #N/A N/A | R8: 16.381 | S8: SPX 2/21/25 P5835 Index | T8: 110 | U8: 100.7 | V8: 101.6 | W8: 101.15 | X8: #N/A N/A | Y8: 15.418 | Z8: =I8*R8+Y8*J8 -> 15.665629 | AA8: 0.15632429
A9: 45671 | B9: 5842.91 | C9: 5845 | D9: 45674 | E9: 45709 | F9: 30 | G9: 3 | H9: 38 | I9: 0.22857143 | J9: 0.77142857 | K9: OK | L9: SPX 1/17/25 P5845 Index | M9: 40.06 | N9: 38 | O9: 39 | P9: 38.5 | Q9: #N/A N/A | R9: 18.418 | S9: SPX 2/21/25 P5845 Index | T9: 96.72 | U9: 97.6 | V9: 99.7 | W9: 98.65 | X9: #N/A N/A | Y9: 15.36 | Z9: =I9*R9+Y9*J9 -> 16.058971 | AA9: 0.15803971
A10: 45672 | B10: 5949.91 | C10: 5950 | D10: 45674 | E10: 45709 | F10: 30 | G10: 2 | H10: 37 | I10: 0.2 | J10: 0.8 | K10: OK | L10: SPX 1/17/25 P5950 Index | M10: 22.9 | N10: 21.8 | O10: 22.5 | P10: 22.15 | Q10: #N/A N/A | R10: 11.912 | S10: SPX 2/21/25 P5950 Index | T10: 85.77 | U10: 85.3 | V10: 86.8 | W10: 86.05 | X10: #N/A N/A | Y10: 13.104 | Z10: =I10*R10+Y10*J10 -> 12.8656 | AA10: 0.127208
A11: 45673 | B11: 5937.34 | C11: 5935 | D11: 45674 | E11: 45709 | F11: 30 | G11: 1 | H11: 36 | I11: 0.17142857 | J11: 0.82857143 | K11: OK | L11: SPX 1/17/25 P5935 Index | M11: 15.5 | N11: 12.4 | O11: 14 | P11: 13.2 | Q11: #N/A N/A | R11: 9.169 | S11: SPX 2/21/25 P5935 Index | T11: 81.35 | U11: 85.3 | V11: 87.1 | W11: 86.2 | X11: #N/A N/A | Y11: 13.214 | Z11: =I11*R11+Y11*J11 -> 12.520571 | AA11: 0.12544929
A12: 45674 | B12: 5996.66 | C12: 5995 | D12: 45709 | E12: 45737 | F12: 30 | G12: 35 | H12: 63 | I12: 1 | J12: 0 | K12: OK | L12: SPX 2/21/25 P5995 Index | M12: 82.5 | N12: 81.7 | O12: 83.4 | P12: 82.55 | Q12: #N/A N/A | R12: 13.061 | S12: SPX 3/21/25 P5995 Index | T12: 110.1 | U12: 112.1 | V12: 113.5 | W12: 112.8 | X12: #N/A N/A | Y12: 13.459 | Z12: =I12*R12+Y12*J12 -> 13.061 | AA12: 0.129615
A13: 45678 | B13: 6049.24 | C13: 6050 | D13: 45709 | E13: 45737 | F13: 30 | G13: 31 | H13: 59 | I13: 1 | J13: 0 | K13: OK | L13: SPX 2/21/25 P6050 Index | M13: 74.8 | N13: 69.9 | O13: 72.4 | P13: 71.15 | Q13: #N/A N/A | R13: 11.864 | S13: SPX 3/21/25 P6050 Index | T13: 101.3 | U13: 99.7 | V13: 102.2 | W13: 100.95 | X13: #N/A N/A | Y13: 12.447 | Z13: =I13*R13+Y13*J13 -> 11.864 | AA13: 0.11738
A14: 45679 | B14: 6086.37 | C14: 6085 | D14: 45709 | E14: 45737 | F14: 30 | G14: 30 | H14: 58 | I14: 1 | J14: 0 | K14: OK | L14: SPX 2/21/25 P6085 Index | M14: 71.5 | N14: 71 | O14: 72.4 | P14: 71.7 | Q14: #N/A N/A | R14: 11.633 | S14: SPX 3/21/25 P6085 Index | T14: 102.12 | U14: 102.1 | V14: 103.4 | W14: 102.75 | X14: #N/A N/A | Y14: 12.433 | Z14: =I14*R14+Y14*J14 -> 11.633 | AA14: 0.11523
A15: 45680 | B15: 6118.71 | C15: 6120 | D15: 45709 | E15: 45737 | F15: 30 | G15: 29 | H15: 57 | I15: 0.96428571 | J15: 0.035714286 | K15: OK | L15: SPX 2/21/25 P6120 Index | M15: 78.57 | N15: 71.8 | O15: 73.5 | P15: 72.65 | Q15: #N/A N/A | R15: 11.534 | S15: SPX 3/21/25 P6120 Index | T15: 102.5 | U15: 103.1 | V15: 104.6 | W15: 103.85 | X15: #N/A N/A | Y15: 12.318 | Z15: =I15*R15+Y15*J15 -> 11.562 | AA15: 0.11435089
... A62: 45748 | B62: 5633.07 | C62: 5635 | D62: 45764 | E62: 45793 | F62: 30 | G62: 16 | H62: 45 | I62: 0.51724138 | J62: 0.48275862 | K62: OK | L62: SPX 4/17/25 P5635 Index | M62: 90.1 | N62: 90.7 | O62: 92.8 | P62: 91.75 | Q62: #N/A N/A | R62: 19.515 | S62: SPX 5/16/25 P5635 Index | T62: 135 | U62: 132.9 | V62: 135.2 | W62: 134.05 | X62: #N/A N/A | Y62: 18.125 | Z62: =I62*R62+Y62*J62 -> 18.843966 | AA62: 0.18690241
A63: 45749 | B63: 5670.97 | C63: 5670 | D63: 45764 | E63: 45793 | F63: 30 | G63: 15 | H63: 44 | I63: 0.48275862 | J63: 0.51724138 | K63: OK | L63: SPX 4/17/25 P5670 Index | M63: 90.93 | N63: 155.9 | O63: 167.3 | P63: 161.6 | Q63: #N/A N/A | R63: 19.342 | S63: SPX 5/16/25 P5670 Index | T63: #N/A N/A | U63: 191.5 | V63: 205.8 | W63: 198.65 | X63: #N/A N/A | Y63: 17.781 | Z63: =I63*R63+Y63*J63 -> 18.534586 | AA63: 0.18502603
A64: 45750 | B64: 5396.52 | C64: 5395 | D64: 45764 | E64: 45793 | F64: 30 | G64: 14 | H64: 43 | I64: 0.44827586 | J64: 0.55172414 | K64: OK | L64: SPX 4/17/25 P5395 Index | M64: 110.3 | N64: 118 | O64: 121.3 | P64: 119.65 | Q64: #N/A N/A | R64: 27.407 | S64: SPX 5/16/25 P5395 Index | T64: 145.98 | U64: 174.1 | V64: 177.6 | W64: 175.85 | X64: #N/A N/A | Y64: 24.295 | Z64: =I64*R64+Y64*J64 -> 25.690034 | AA64: 0.25583621
A65: 45751 | B65: 5074.08 | C65: 5075 | D65: 45764 | E65: 45793 | F65: 30 | G65: 13 | H65: 42 | I65: 0.4137931 | J65: 0.5862069 | K65: OK | L65: SPX 4/17/25 P5075 Index | M65: 175.16 | N65: 175 | O65: 179.2 | P65: 177.1 | Q65: #N/A N/A | R65: 44.582 | S65: SPX 5/16/25 P5075 Index | T65: 216.48 | U65: 233.2 | V65: 237 | W65: 235.1 | X65: #N/A N/A | Y65: 34.284 | Z65: =I65*R65+Y65*J65 -> 38.545241 | AA65: 0.38442862
A66: 45754 | B66: 5062.25 | C66: 5060 | D66: 45764 | E66: 45793 | F66: 30 | G66: 10 | H66: 39 | I66: 0.31034483 | J66: 0.68965517 | K66: OK | L66: SPX 4/17/25 P5060 Index | M66: 217.51 | N66: 162.9 | O66: 168.3 | P66: 165.6 | Q66: #N/A N/A | R66: 50.957 | S66: SPX 5/16/25 P5060 Index | T66: 211.71 | U66: 218.4 | V66: 224.7 | W66: 221.55 | X66: #N/A N/A | Y66: 36.343 | Z66: =I66*R66+Y66*J66 -> 40.878379 | AA66: 0.40649741
A67: 45755 | B67: 4982.77 | C67: 4985 | D67: 45764 | E67: 45793 | F67: 30 | G67: 9 | H67: 38 | I67: 0.27586207 | J67: 0.72413793 | K67: OK | L67: SPX 4/17/25 P4985 Index | M67: 176.1 | N67: 176.3 | O67: 183.3 | P67: 179.8 | Q67: #N/A N/A | R67: 55.077 | S67: SPX 5/16/25 P4985 Index | T67: 207.6 | U67: 244.9 | V67: 257.1 | W67: 251 | X67: #N/A N/A | Y67: 39.613 | Z67: =I67*R67+Y67*J67 -> 43.878931 | AA67: 0.43813069
A68: 45756 | B68: 5456.9 | C68: 5455 | D68: 45764 | E68: 45793 | F68: 30 | G68: 8 | H68: 37 | I68: 0.24137931 | J68: 0.75862069 | K68: OK | L68: SPX 4/17/25 P5455 Index | M68: 108.4 | N68: 93.6 | O68: 98.1 | P68: 95.85 | Q68: #N/A N/A | R68: 32.882 | S68: SPX 5/16/25 P5455 Index | T68: 168.06 | U68: 154.9 | V68: 160.8 | W68: 157.85 | X68: #N/A N/A | Y68: 25.341 | Z68: =I68*R68+Y68*J68 -> 27.161241 | AA68: 0.27597
A69: 45757 | B69: 5268.05 | C69: 5270 | D69: 45764 | E69: 45793 | F69: 30 | G69: 7 | H69: 36 | I69: 0.20689655 | J69: 0.79310345 | K69: OK | L69: SPX 4/17/25 P5270 Index | M69: 131.97 | N69: 128.2 | O69: 134.3 | P69: 131.25 | Q69: #N/A N/A | R69: 45.923 | S69: SPX 5/16/25 P5270 Index | T69: 214.65 | U69: 211.9 | V69: 216.5 | W69: 214.2 | X69: #N/A N/A | Y69: 33.424 | Z69: =I69*R69+Y69*J69 -> 36.01 | AA69: 0.36169672
A70: 45758 | B70: 5363.36 | C70: 5365 | D70: 45764 | E70: 45793 | F70: 30 | G70: 6 | H70: 35 | I70: 0.17241379 | J70: 0.82758621 | K70: OK | L70: SPX 4/17/25 P5365 Index | M70: 102 | N70: 103.4 | O70: 106.9 | P70: 105.15 | Q70: #N/A N/A | R70: 39.617 | S70: SPX 5/16/25 P5365 Index | T70: 208.1 | U70: 196.9 | V70: 200.8 | W70: 198.85 | X70: #N/A N/A | Y70: 31.252 | Z70: =I70*R70+Y70*J70 -> 32.694241 | AA70: 0.32767569
A71: 45761 | B71: 5405.97 | C71: 5405 | D71: 45764 | E71: 45793 | F71: 30 | G71: 3 | H71: 32 | I71: 0.068965517 | J71: 0.93103448 | K71: OK | L71: SPX 4/17/25 P5405 Index | M71: 59.7 | N71: 62 | O71: 64.1 | P71: 63.05 | Q71: #N/A N/A | R71: 27.301 | S71: SPX 5/16/25 P5405 Index | T71: 155.75 | U71: 160.2 | V71: 163.4 | W71: 161.8 | X71: #N/A N/A | Y71: 25.702 | Z71: =I71*R71+Y71*J71 -> 25.812276 | AA71: 0.25725017
A72: 45762 | B72: 5396.63 | C72: 5395 | D72: 45764 | E72: 45793 | F72: 30 | G72: 2 | H72: 31 | I72: 0.034482759 | J72: 0.96551724 | K72: OK | L72: SPX 4/17/25 P5395 Index | M72: 35.4 | N72: 37.9 | O72: 39.6 | P72: 38.75 | Q72: #N/A N/A | R72: 21.337 | S72: SPX 5/16/25 P5395 Index | T72: 148.3 | U72: 149.3 | V72: 151.4 | W72: 150.35 | X72: #N/A N/A | Y72: 24.891 | Z72: =I72*R72+Y72*J72 -> 24.768448 | AA72: 0.24702017
A73: 45763 | B73: 5275.7 | C73: 5275 | D73: 45764 | E73: 45793 | F73: 30 | G73: 1 | H73: 30 | I73: 0 | J73: 1 | K73: OK | L73: SPX 4/17/25 P5275 Index | M73: 30 | N73: 33.7 | O73: 35.8 | P73: 34.75 | Q73: #N/A N/A | R73: 27.208 | S73: SPX 5/16/25 P5275 Index | T73: 162.1 | U73: 165.3 | V73: 169 | W73: 167.15 | X73: #N/A N/A | Y73: 27.991 | Z73: =I73*R73+Y73*J73 -> 27.991 | AA73: 0.27919
A74: 45764 | B74: 5282.7 | C74: 5285 | D74: 45793 | E74: 45828 | F74: 30 | G74: 29 | H74: 64 | I74: 0 | J74: 1 | K74: OK | L74: SPX 5/16/25 P5285 Index | M74: 151.6 | N74: 140.5 | O74: 143.5 | P74: 142 | Q74: #N/A N/A | R74: 26.341 | S74: SPX 6/20/25 P5285 Index | T74: 200.91 | U74: 196 | V74: 199.1 | W74: 197.55 | X74: #N/A N/A | Y74: 25.233 | Z74: =I74*R74+Y74*J74 -> 25.233 | AA74: 0.25081
A75: 45768 | B75: 5158.2 | C75: 5160 | D75: 45793 | E75: 45828 | F75: 30 | G75: 25 | H75: 60 | I75: 0.85714286 | J75: 0.14285714 | K75: OK | L75: SPX 5/16/25 P5160 Index | M75: 159.84 | N75: 158.7 | O75: 160.8 | P75: 159.75 | Q75: #N/A N/A | R75: 29.402 | S75: SPX 6/20/25 P5160 Index | T75: 219.48 | U75: 214.9 | V75: 217 | W75: 215.95 | X75: #N/A N/A | Y75: 27.448 | Z75: =I75*R75+Y75*J75 -> 29.122857 | AA75: 0.28958429
... A162: 45894 | B162: 6439.32 | C162: 6440 | D162: 45919 | E162: 45947 | F162: 30 | G162: 25 | H162: 53 | I162: 0.82142857 | J162: 0.17857143 | K162: OK | L162: SPX 9/19/25 P6440 Index | M162: 69.1 | N162: 68.5 | O162: 69.6 | P162: 69.05 | Q162: #N/A N/A | R162: 11.51 | S162: SPX 10/17/25 P6440 Index | T162: 101.5 | U162: 105.2 | V162: 106.4 | W162: 105.8 | X162: #N/A N/A | Y162: 12.544 | Z162: =I162*R162+Y162*J162 -> 11.694643 | AA162: 0.11629268
A163: 45895 | B163: 6465.94 | C163: 6465 | D163: 45919 | E163: 45947 | F163: 30 | G163: 24 | H163: 52 | I163: 0.78571429 | J163: 0.21428571 | K163: OK | L163: SPX 9/19/25 P6465 Index | M163: 65.6 | N163: 64 | O163: 65.1 | P163: 64.55 | Q163: #N/A N/A | R163: 11.379 | S163: SPX 10/17/25 P6465 Index | T163: #N/A N/A | U163: 100.5 | V163: 102.2 | W163: 101.35 | X163: #N/A N/A | Y163: 12.366 | Z163: =I163*R163+Y163*J163 -> 11.5905 | AA163: 0.11574786
A164: 45896 | B164: 6481.4 | C164: 6480 | D164: 45919 | E164: 45947 | F164: 30 | G164: 23 | H164: 51 | I164: 0.75 | J164: 0.25 | K164: OK | L164: SPX 9/19/25 P6480 Index | M164: 68.68 | N164: 69.8 | O164: 71.3 | P164: 70.55 | Q164: #N/A N/A | R164: 11.706 | S164: SPX 10/17/25 P6480 Index | T164: 106.7 | U164: 106 | V164: 108.1 | W164: 107.05 | X164: #N/A N/A | Y164: 12.451 | Z164: =I164*R164+Y164*J164 -> 11.89225 | AA164: 0.11841375
A165: 45897 | B165: 6501.86 | C165: 6500 | D165: 45919 | E165: 45947 | F165: 30 | G165: 22 | H165: 50 | I165: 0.71428571 | J165: 0.28571429 | K165: OK | L165: SPX 9/19/25 P6500 Index | M165: 61.57 | N165: 61.2 | O165: 62.5 | P165: 61.85 | Q165: #N/A N/A | R165: 11.114 | S165: SPX 10/17/25 P6500 Index | T165: 99.6 | U165: 99.3 | V165: 100.8 | W165: 100.05 | X165: #N/A N/A | Y165: 12.238 | Z165: =I165*R165+Y165*J165 -> 11.435143 | AA165: 0.11395857
A166: 45898 | B166: 6460.26 | C166: 6460 | D166: 45919 | E166: 45947 | F166: 30 | G166: 21 | H166: 49 | I166: 0.67857143 | J166: 0.32142857 | K166: OK | L166: SPX 9/19/25 P6460 Index | M166: 66.6 | N166: 65.8 | O166: 67.2 | P166: 66.5 | Q166: #N/A N/A | R166: 12.034 | S166: SPX 10/17/25 P6460 Index | T166: 107.7 | U166: 103.9 | V166: 105.9 | W166: 104.9 | X166: #N/A N/A | Y166: 12.768 | Z166: =I166*R166+Y166*J166 -> 12.269929 | AA166: 0.12291964
A167: 45902 | B167: 6415.54 | C167: 6415 | D167: 45919 | E167: 45947 | F167: 30 | G167: 17 | H167: 45 | I167: 0.53571429 | J167: 0.46428571 | K167: OK | L167: SPX 9/19/25 P6415 Index | M167: 72.5 | N167: 60.2 | O167: 61.2 | P167: 60.7 | Q167: #N/A N/A | R167: 13.341 | S167: SPX 10/17/25 P6415 Index | T167: 110.15 | U167: 99.7 | V167: 101.1 | W167: 100.4 | X167: #N/A N/A | Y167: 13.63 | Z167: =I167*R167+Y167*J167 -> 13.475179 | AA167: 0.13333893
A168: 45903 | B168: 6448.26 | C168: 6450 | D168: 45919 | E168: 45947 | F168: 30 | G168: 16 | H168: 44 | I168: 0.5 | J168: 0.5 | K168: OK | L168: SPX 9/19/25 P6450 Index | M168: 63.1 | N168: 62.4 | O168: 63.4 | P168: 62.9 | Q168: #N/A N/A | R168: 12.258 | S168: SPX 10/17/25 P6450 Index | T168: 106.5 | U168: 102.8 | V168: 104.2 | W168: 103.5 | X168: #N/A N/A | Y168: 12.965 | Z168: =I168*R168+Y168*J168 -> 12.6115 | AA168: 0.1257325
A169: 45904 | B169: 6502.08 | C169: 6500 | D169: 45919 | E169: 45947 | F169: 30 | G169: 15 | H169: 43 | I169: 0.46428571 | J169: 0.53571429 | K169: OK | L169: SPX 9/19/25 P6500 Index | M169: 54.3 | N169: 53.6 | O169: 54.8 | P169: 54.2 | Q169: #N/A N/A | R169: 11.273 | S169: SPX 10/17/25 P6500 Index | T169: 95 | U169: 95.3 | V169: 96.5 | W169: 95.9 | X169: #N/A N/A | Y169: 12.367 | Z169: =I169*R169+Y169*J169 -> 11.859071 | AA169: 0.11833768
A170: 45905 | B170: 6481.5 | C170: 6480 | D170: 45919 | E170: 45947 | F170: 30 | G170: 14 | H170: 42 | I170: 0.42857143 | J170: 0.57142857 | K170: OK | L170: SPX 9/19/25 P6480 Index | M170: 51.85 | N170: 50.9 | O170: 52.2 | P170: 51.55 | Q170: #N/A N/A | R170: 11.014 | S170: SPX 10/17/25 P6480 Index | T170: 95.03 | U170: 94.3 | V170: 96.9 | W170: 95.6 | X170: #N/A N/A | Y170: 12.342 | Z170: =I170*R170+Y170*J170 -> 11.772857 | AA170: 0.117355
A171: 45908 | B171: 6495.15 | C171: 6495 | D171: 45919 | E171: 45947 | F171: 30 | G171: 11 | H171: 39 | I171: 0.32142857 | J171: 0.67857143 | K171: OK | L171: SPX 9/19/25 P6495 Index | M171: 46.15 | N171: 44.6 | O171: 45.6 | P171: 45.1 | Q171: #N/A N/A | R171: 10.603 | S171: SPX 10/17/25 P6495 Index | T171: 93 | U171: 89 | V171: 90.4 | W171: 89.7 | X171: #N/A N/A | Y171: 12.01 | Z171: =I171*R171+Y171*J171 -> 11.55775 | AA171: 0.11521018
A172: 45909 | B172: 6512.61 | C172: 6515 | D172: 45919 | E172: 45947 | F172: 30 | G172: 10 | H172: 38 | I172: 0.28571429 | J172: 0.71428571 | K172: OK | L172: SPX 9/19/25 P6515 Index | M172: 43.69 | N172: 40.7 | O172: 41.9 | P172: 41.3 | Q172: #N/A N/A | R172: 10.477 | S172: SPX 10/17/25 P6515 Index | T172: 93.15 | U172: 85.5 | V172: 87.6 | W172: 86.55 | X172: #N/A N/A | Y172: 11.888 | Z172: =I172*R172+Y172*J172 -> 11.484857 | AA172: 0.114785
...

Sheet IV
A1: Date | B1: IV_30D_Call(%) | C1: IV_30D_Put(%) | D1: IV_30D=(B2+C2)/2 | E1: Proxy=C2-B2(%)
A2: 45659 | B2: =VLOOKUP(A2, Call!A:Z, 26, FALSE) -> 14.337 | C2: =VLOOKUP(A2, Put!A:Z, 26, FALSE) -> 14.475429 | D2: =(B2+C2)/200 -> 0.14406214 | E2: =C2-B2 -> 0.13842857
A3: 45660 | B3: =VLOOKUP(A3, Call!A:Z, 26, FALSE) -> 12.571114 | C3: =VLOOKUP(A3, Put!A:Z, 26, FALSE) -> 12.941371 | D3: =(B3+C3)/200 -> 0.12756243 | E3: =C3-B3 -> 0.37025714
A4: 45663 | B4: =VLOOKUP(A4, Call!A:Z, 26, FALSE) -> 12.598857 | C4: =VLOOKUP(A4, Put!A:Z, 26, FALSE) -> 13.037486 | D4: =(B4+C4)/200 -> 0.12818171 | E4: =C4-B4 -> 0.43862857
A5: 45664 | B5: =VLOOKUP(A5, Call!A:Z, 26, FALSE) -> 14.369143 | C5: =VLOOKUP(A5, Put!A:Z, 26, FALSE) -> 14.670571 | D5: =(B5+C5)/200 -> 0.14519857 | E5: =C5-B5 -> 0.30142857
A6: 45665 | B6: =VLOOKUP(A6, Call!A:Z, 26, FALSE) -> 14.3038 | C6: =VLOOKUP(A6, Put!A:Z, 26, FALSE) -> 14.5744 | D6: =(B6+C6)/200 -> 0.144391 | E6: =C6-B6 -> 0.2706
A7: 45667 | B7: =VLOOKUP(A7, Call!A:Z, 26, FALSE) -> 15.8656 | C7: =VLOOKUP(A7, Put!A:Z, 26, FALSE) -> 15.908029 | D7: =(B7+C7)/200 -> 0.15886814 | E7: =C7-B7 -> 0.042428571
A8: 45670 | B8: =VLOOKUP(A8, Call!A:Z, 26, FALSE) -> 15.599229 | C8: =VLOOKUP(A8, Put!A:Z, 26, FALSE) -> 15.665629 | D8: =(B8+C8)/200 -> 0.15632429 | E8: =C8-B8 -> 0.0664
A9: 45671 | B9: =VLOOKUP(A9, Call!A:Z, 26, FALSE) -> 15.548971 | C9: =VLOOKUP(A9, Put!A:Z, 26, FALSE) -> 16.058971 | D9: =(B9+C9)/200 -> 0.15803971 | E9: =C9-B9 -> 0.51
A10: 45672 | B10: =VLOOKUP(A10, Call!A:Z, 26, FALSE) -> 12.576 | C10: =VLOOKUP(A10, Put!A:Z, 26, FALSE) -> 12.8656 | D10: =(B10+C10)/200 -> 0.127208 | E10: =C10-B10 -> 0.2896
A11: 45673 | B11: =VLOOKUP(A11, Call!A:Z, 26, FALSE) -> 12.569286 | C11: =VLOOKUP(A11, Put!A:Z, 26, FALSE) -> 12.520571 | D11: =(B11+C11)/200 -> 0.12544929 | E11: =C11-B11 -> -0.048714286
A12: 45674 | B12: =VLOOKUP(A12, Call!A:Z, 26, FALSE) -> 12.862 | C12: =VLOOKUP(A12, Put!A:Z, 26, FALSE) -> 13.061 | D12: =(B12+C12)/200 -> 0.129615 | E12: =C12-B12 -> 0.199
A13: 45678 | B13: =VLOOKUP(A13, Call!A:Z, 26, FALSE) -> 11.612 | C13: =VLOOKUP(A13, Put!A:Z, 26, FALSE) -> 11.864 | D13: =(B13+C13)/200 -> 0.11738 | E13: =C13-B13 -> 0.252
... A251: 46022 | B251: =VLOOKUP(A251, Call!A:Z, 26, FALSE) -> 12.1546 | C251: =VLOOKUP(A251, Put!A:Z, 26, FALSE) -> 12.3266 | D251: =(B251+C251)/200 -> 0.122406 | E251: =C251-B251 -> 0.172

Sheet Straddle
A1: Date | B1: Front_Call_Mid | C1: Front_Put_Mid | D1: Next_Call_Mid | E1: Next_Put_Mid | F1: Front_Straddle | G1: Next_Straddle | H1: Weighted_Front | I1: Weighted_N | J1: 30D Constant-Maturity Straddle | K1: PnL | L1: Return | M1: Cumulative PnL
A2: 45659 | B2: =VLOOKUP(A2, Call!A:P, 16, FALSE) -> 75.8 | C2: =VLOOKUP(A2, Put!A:P, 16, FALSE) -> 63.25 | D2: =VLOOKUP(A2, Call!A:W, 23, FALSE) -> 141.2 | E2: =VLOOKUP(A2, Put!A:W, 23, FALSE) -> 108 | F2: =B2+C2 -> 139.05 | G2: =D2+E2 -> 249.2 | H2: =VLOOKUP(A2, Call!A:I, 9, FALSE) -> 0.57142857 | I2: =VLOOKUP(A2, Call!A:J, 10, FALSE) -> 0.42857143 | J2: =F2*H2+G2*I2 -> 186.25714 | K2: 0 | L2: 0 | M2: 0
A3: 45660 | B3: =VLOOKUP(A3, Call!A:P, 16, FALSE) -> 61.55 | C3: =VLOOKUP(A3, Put!A:P, 16, FALSE) -> 53.95 | D3: =VLOOKUP(A3, Call!A:W, 23, FALSE) -> 128.8 | E3: =VLOOKUP(A3, Put!A:W, 23, FALSE) -> 100.3 | F3: =B3+C3 -> 115.5 | G3: =D3+E3 -> 229.1 | H3: =VLOOKUP(A3, Call!A:I, 9, FALSE) -> 0.54285714 | I3: =VLOOKUP(A3, Call!A:J, 10, FALSE) -> 0.45714286 | J3: =F3*H3+G3*I3 -> 167.43143 | K3: =J3-J2 -> -18.825714 | L3: =(J3-J2)/J2 -> -0.10107378 | M3: =M2 + K3 -> -18.825714
A4: 45663 | B4: =VLOOKUP(A4, Call!A:P, 16, FALSE) -> 60.25 | C4: =VLOOKUP(A4, Put!A:P, 16, FALSE) -> 44.9 | D4: =VLOOKUP(A4, Call!A:W, 23, FALSE) -> 127.95 | E4: =VLOOKUP(A4, Put!A:W, 23, FALSE) -> 91.85 | F4: =B4+C4 -> 105.15 | G4: =D4+E4 -> 219.8 | H4: =VLOOKUP(A4, Call!A:I, 9, FALSE) -> 0.45714286 | I4: =VLOOKUP(A4, Call!A:J, 10, FALSE) -> 0.54285714 | J4: =F4*H4+G4*I4 -> 167.38857 | K4: =J4-J3 -> -0.042857143 | L4: =(J4-J3)/J3 -> -0.00025596833 | M4: =M3 + K4 -> -18.868571
A5: 45664 | B5: =VLOOKUP(A5, Call!A:P, 16, FALSE) -> 59.95 | C5: =VLOOKUP(A5, Put!A:P, 16, FALSE) -> 53.2 | D5: =VLOOKUP(A5, Call!A:W, 23, FALSE) -> 131.4 | E5: =VLOOKUP(A5, Put!A:W, 23, FALSE) -> 104.1 | F5: =B5+C5 -> 113.15 | G5: =D5+E5 -> 235.5 | H5: =VLOOKUP(A5, Call!A:I, 9, FALSE) -> 0.42857143 | I5: =VLOOKUP(A5, Call!A:J, 10, FALSE) -> 0.57142857 | J5: =F5*H5+G5*I5 -> 183.06429 | K5: =J5-J4 -> 15.675714 | L5: =(J5-J4)/J4 -> 0.093648653 | M5: =M4 + K5 -> -3.1928571
A6: 45665 | B6: =VLOOKUP(A6, Call!A:P, 16, FALSE) -> 52.1 | C6: =VLOOKUP(A6, Put!A:P, 16, FALSE) -> 53.55 | D6: =VLOOKUP(A6, Call!A:W, 23, FALSE) -> 124.4 | E6: =VLOOKUP(A6, Put!A:W, 23, FALSE) -> 106 | F6: =B6+C6 -> 105.65 | G6: =D6+E6 -> 230.4 | H6: =VLOOKUP(A6, Call!A:I, 9, FALSE) -> 0.4 | I6: =VLOOKUP(A6, Call!A:J, 10, FALSE) -> 0.6 | J6: =F6*H6+G6*I6 -> 180.5 | K6: =J6-J5 -> -2.5642857 | L6: =(J6-J5)/J5 -> -0.01400757 | M6: =M5 + K6 -> -5.7571429
A7: 45667 | B7: =VLOOKUP(A7, Call!A:P, 16, FALSE) -> 52.6 | C7: =VLOOKUP(A7, Put!A:P, 16, FALSE) -> 51.3 | D7: =VLOOKUP(A7, Call!A:W, 23, FALSE) -> 132 | E7: =VLOOKUP(A7, Put!A:W, 23, FALSE) -> 111.15 | F7: =B7+C7 -> 103.9 | G7: =D7+E7 -> 243.15 | H7: =VLOOKUP(A7, Call!A:I, 9, FALSE) -> 0.34285714 | I7: =VLOOKUP(A7, Call!A:J, 10, FALSE) -> 0.65714286 | J7: =F7*H7+G7*I7 -> 195.40714 | K7: =J7-J6 -> 14.907143 | L7: =(J7-J6)/J6 -> 0.082588049 | M7: =M6 + K7 -> 9.15
A8: 45670 | B8: =VLOOKUP(A8, Call!A:P, 16, FALSE) -> 52.9 | C8: =VLOOKUP(A8, Put!A:P, 16, FALSE) -> 41.4 | D8: =VLOOKUP(A8, Call!A:W, 23, FALSE) -> 132.3 | E8: =VLOOKUP(A8, Put!A:W, 23, FALSE) -> 101.15 | F8: =B8+C8 -> 94.3 | G8: =D8+E8 -> 233.45 | H8: =VLOOKUP(A8, Call!A:I, 9, FALSE) -> 0.25714286 | I8: =VLOOKUP(A8, Call!A:J, 10, FALSE) -> 0.74285714 | J8: =F8*H8+G8*I8 -> 197.66857 | K8: =J8-J7 -> 2.2614286 | L8: =(J8-J7)/J7 -> 0.011572906 | M8: =M7 + K8 -> 11.411429
A9: 45671 | B9: =VLOOKUP(A9, Call!A:P, 16, FALSE) -> 48.45 | C9: =VLOOKUP(A9, Put!A:P, 16, FALSE) -> 38.5 | D9: =VLOOKUP(A9, Call!A:W, 23, FALSE) -> 128.8 | E9: =VLOOKUP(A9, Put!A:W, 23, FALSE) -> 98.65 | F9: =B9+C9 -> 86.95 | G9: =D9+E9 -> 227.45 | H9: =VLOOKUP(A9, Call!A:I, 9, FALSE) -> 0.22857143 | I9: =VLOOKUP(A9, Call!A:J, 10, FALSE) -> 0.77142857 | J9: =F9*H9+G9*I9 -> 195.33571 | K9: =J9-J8 -> -2.3328571 | L9: =(J9-J8)/J8 -> -0.011801862 | M9: =M8 + K9 -> 9.0785714
A10: 45672 | B10: =VLOOKUP(A10, Call!A:P, 16, FALSE) -> 23.15 | C10: =VLOOKUP(A10, Put!A:P, 16, FALSE) -> 22.15 | D10: =VLOOKUP(A10, Call!A:W, 23, FALSE) -> 107.6 | E10: =VLOOKUP(A10, Put!A:W, 23, FALSE) -> 86.05 | F10: =B10+C10 -> 45.3 | G10: =D10+E10 -> 193.65 | H10: =VLOOKUP(A10, Call!A:I, 9, FALSE) -> 0.2 | I10: =VLOOKUP(A10, Call!A:J, 10, FALSE) -> 0.8 | J10: =F10*H10+G10*I10 -> 163.98 | K10: =J10-J9 -> -31.355714 | L10: =(J10-J9)/J9 -> -0.16052218 | M10: =M9 + K10 -> -22.277143
A11: 45673 | B11: =VLOOKUP(A11, Call!A:P, 16, FALSE) -> 12 | C11: =VLOOKUP(A11, Put!A:P, 16, FALSE) -> 13.2 | D11: =VLOOKUP(A11, Call!A:W, 23, FALSE) -> 105.05 | E11: =VLOOKUP(A11, Put!A:W, 23, FALSE) -> 86.2 | F11: =B11+C11 -> 25.2 | G11: =D11+E11 -> 191.25 | H11: =VLOOKUP(A11, Call!A:I, 9, FALSE) -> 0.17142857 | I11: =VLOOKUP(A11, Call!A:J, 10, FALSE) -> 0.82857143 | J11: =F11*H11+G11*I11 -> 162.78429 | K11: =J11-J10 -> -1.1957143 | L11: =(J11-J10)/J10 -> -0.00729183 | M11: =M10 + K11 -> -23.472857
A12: 45674 | B12: =VLOOKUP(A12, Call!A:P, 16, FALSE) -> 104.25 | C12: =VLOOKUP(A12, Put!A:P, 16, FALSE) -> 82.55 | D12: =VLOOKUP(A12, Call!A:W, 23, FALSE) -> 149.95 | E12: =VLOOKUP(A12, Put!A:W, 23, FALSE) -> 112.8 | F12: =B12+C12 -> 186.8 | G12: =D12+E12 -> 262.75 | H12: =VLOOKUP(A12, Call!A:I, 9, FALSE) -> 1 | I12: =VLOOKUP(A12, Call!A:J, 10, FALSE) -> 0 | J12: =F12*H12+G12*I12 -> 186.8 | K12: =J12-J11 -> 24.015714 | L12: =(J12-J11)/J11 -> 0.14753091 | M12: =M11 + K12 -> 0.54285714
A13: 45678 | B13: =VLOOKUP(A13, Call!A:P, 16, FALSE) -> 96.1 | C13: =VLOOKUP(A13, Put!A:P, 16, FALSE) -> 71.15 | D13: =VLOOKUP(A13, Call!A:W, 23, FALSE) -> 142.35 | E13: =VLOOKUP(A13, Put!A:W, 23, FALSE) -> 100.95 | F13: =B13+C13 -> 167.25 | G13: =D13+E13 -> 243.3 | H13: =VLOOKUP(A13, Call!A:I, 9, FALSE) -> 1 | I13: =VLOOKUP(A13, Call!A:J, 10, FALSE) -> 0 | J13: =F13*H13+G13*I13 -> 167.25 | K13: =J13-J12 -> -19.55 | L13: =(J13-J12)/J12 -> -0.10465739 | M13: =M12 + K13 -> -19.007143
A14: 45679 | B14: =VLOOKUP(A14, Call!A:P, 16, FALSE) -> 89.7 | C14: =VLOOKUP(A14, Put!A:P, 16, FALSE) -> 71.7 | D14: =VLOOKUP(A14, Call!A:W, 23, FALSE) -> 137.7 | E14: =VLOOKUP(A14, Put!A:W, 23, FALSE) -> 102.75 | F14: =B14+C14 -> 161.4 | G14: =D14+E14 -> 240.45 | H14: =VLOOKUP(A14, Call!A:I, 9, FALSE) -> 1 | I14: =VLOOKUP(A14, Call!A:J, 10, FALSE) -> 0 | J14: =F14*H14+G14*I14 -> 161.4 | K14: =J14-J13 -> -5.85 | L14: =(J14-J13)/J13 -> -0.034977578 | M14: =M13 + K14 -> -24.857143
... A251: 46022 | B251: =VLOOKUP(A251, Call!A:P, 16, FALSE) -> 72.15 | C251: =VLOOKUP(A251, Put!A:P, 16, FALSE) -> 58.35 | D251: =VLOOKUP(A251, Call!A:W, 23, FALSE) -> 148.1 | E251: =VLOOKUP(A251, Put!A:W, 23, FALSE) -> 115 | F251: =B251+C251 -> 130.5 | G251: =D251+E251 -> 263.1 | H251: =VLOOKUP(A251, Call!A:I, 9, FALSE) -> 0.6 | I251: =VLOOKUP(A251, Call!A:J, 10, FALSE) -> 0.4 | J251: =F251*H251+G251*I251 -> 183.54 | K251: =J251-J250 -> 6.0657143 | L251: =(J251-J250)/J250 -> 0.03417799 | M251: =M250 + K251 -> -2.7171429

Sheet Delta_interpolation
A1: Date | B1: Underlying (SPX Spot) | C1: ATM Strike | D1: IV_30D(call+put)/2 | E1: RF_1M/100 | F1: T(30/365) | G1: Call delta | H1: Put delta | I1: Straddle delta | J1: Hedge
A2: 45659 | B2: 5868.55 | C2: 5870 | D2: 0.14406214 | E2: 0.042912 | F2: =30/365 -> 0.082191781 | G2: =_xlfn.NORM.S.DIST((LN(B2/C2)+(E2+0.5*(D2)^2)*F2)/(D2*SQRT(F2)),TRUE) -> 0.53985409 | H2: =G2-1 -> -0.46014591 | I2: =G2+H2 -> 0.079708175 | J2: =-I2 -> -0.079708175
A3: 45660 | B3: 5942.47 | C3: 5940 | D3: 0.12756243 | E3: 0.042626 | F3: =30/365 -> 0.082191781 | G3: =_xlfn.NORM.S.DIST((LN(B3/C3)+(E3+0.5*(D3)^2)*F3)/(D3*SQRT(F3)),TRUE) -> 0.54991777 | H3: =G3-1 -> -0.45008223 | I3: =G3+H3 -> 0.099835537 | J3: =-I3 -> -0.099835537
A4: 45663 | B4: 5975.38 | C4: 5975 | D4: 0.12818171 | E4: 0.043106 | F4: =30/365 -> 0.082191781 | G4: =_xlfn.NORM.S.DIST((LN(B4/C4)+(E4+0.5*(D4)^2)*F4)/(D4*SQRT(F4)),TRUE) -> 0.54637808 | H4: =G4-1 -> -0.45362192 | I4: =G4+H4 -> 0.09275615 | J4: =-I4 -> -0.09275615
A5: 45664 | B5: 5909.03 | C5: 5910 | D5: 0.14519857 | E5: 0.043024 | F5: =30/365 -> 0.082191781 | G5: =_xlfn.NORM.S.DIST((LN(B5/C5)+(E5+0.5*(D5)^2)*F5)/(D5*SQRT(F5)),TRUE) -> 0.54055033 | H5: =G5-1 -> -0.45944967 | I5: =G5+H5 -> 0.081100665 | J5: =-I5 -> -0.081100665
A6: 45665 | B6: 5918.25 | C6: 5920 | D6: 0.144391 | E6: 0.042942 | F6: =30/365 -> 0.082191781 | G6: =_xlfn.NORM.S.DIST((LN(B6/C6)+(E6+0.5*(D6)^2)*F6)/(D6*SQRT(F6)),TRUE) -> 0.53935856 | H6: =G6-1 -> -0.46064144 | I6: =G6+H6 -> 0.078717115 | J6: =-I6 -> -0.078717115
A7: 45667 | B7: 5827.04 | C7: 5825 | D7: 0.15886814 | E7: 0.04283 | F7: =30/365 -> 0.082191781 | G7: =_xlfn.NORM.S.DIST((LN(B7/C7)+(E7+0.5*(D7)^2)*F7)/(D7*SQRT(F7)),TRUE) -> 0.54290352 | H7: =G7-1 -> -0.45709648 | I7: =G7+H7 -> 0.085807035 | J7: =-I7 -> -0.085807035
A8: 45670 | B8: 5836.22 | C8: 5835 | D8: 0.15632429 | E8: 0.043055 | F8: =30/365 -> 0.082191781 | G8: =_xlfn.NORM.S.DIST((LN(B8/C8)+(E8+0.5*(D8)^2)*F8)/(D8*SQRT(F8)),TRUE) -> 0.54222229 | H8: =G8-1 -> -0.45777771 | I8: =G8+H8 -> 0.084444585 | J8: =-I8 -> -0.084444585
A9: 45671 | B9: 5842.91 | C9: 5845 | D9: 0.15803971 | E9: 0.042998 | F9: =30/365 -> 0.082191781 | G9: =_xlfn.NORM.S.DIST((LN(B9/C9)+(E9+0.5*(D9)^2)*F9)/(D9*SQRT(F9)),TRUE) -> 0.53695339 | H9: =G9-1 -> -0.46304661 | I9: =G9+H9 -> 0.073906781 | J9: =-I9 -> -0.073906781
A10: 45672 | B10: 5949.91 | C10: 5950 | D10: 0.127208 | E10: 0.042917 | F10: =30/365 -> 0.082191781 | G10: =_xlfn.NORM.S.DIST((LN(B10/C10)+(E10+0.5*(D10)^2)*F10)/(D10*SQRT(F10)),TRUE) -> 0.54559624 | H10: =G10-1 -> -0.45440376 | I10: =G10+H10 -> 0.091192477 | J10: =-I10 -> -0.091192477
A11: 45673 | B11: 5937.34 | C11: 5935 | D11: 0.12544929 | E11: 0.042963 | F11: =30/365 -> 0.082191781 | G11: =_xlfn.NORM.S.DIST((LN(B11/C11)+(E11+0.5*(D11)^2)*F11)/(D11*SQRT(F11)),TRUE) -> 0.55058005 | H11: =G11-1 -> -0.44941995 | I11: =G11+H11 -> 0.10116011 | J11: =-I11 -> -0.10116011
A12: 45674 | B12: 5996.66 | C12: 5995 | D12: 0.129615 | E12: 0.043004 | F12: =30/365 -> 0.082191781 | G12: =_xlfn.NORM.S.DIST((LN(B12/C12)+(E12+0.5*(D12)^2)*F12)/(D12*SQRT(F12)),TRUE) -> 0.54821365 | H12: =G12-1 -> -0.45178635 | I12: =G12+H12 -> 0.096427307 | J12: =-I12 -> -0.096427307
A13: 45678 | B13: 6049.24 | C13: 6050 | D13: 0.11738 | E13: 0.042998 | F13: =30/365 -> 0.082191781 | G13: =_xlfn.NORM.S.DIST((LN(B13/C13)+(E13+0.5*(D13)^2)*F13)/(D13*SQRT(F13)),TRUE) -> 0.54701048 | H13: =G13-1 -> -0.45298952 | I13: =G13+H13 -> 0.094020964 | J13: =-I13 -> -0.094020964
... A251: 46022 | B251: 6845.5 | C251: 6845 | D251: 0.122406 | E251: 0.035904 | F251: =30/365 -> 0.082191781 | G251: =_xlfn.NORM.S.DIST((LN(B251/C251)+(E251+0.5*(D251)^2)*F251)/(D251*SQRT(F251)),TRUE) -> 0.54130411 | H251: =G251-1 -> -0.45869589 | I251: =G251+H251 -> 0.082608227 | J251: =-I251 -> -0.082608227

Sheet Delta_Trading
A1: Date | B1: Underlying (SPX Spot) | C1: ATM Strike | D1: DTE_F = FrontExp - Date | E1: DTE_N = NextExp - Date | F1: IV_Front | G1: IV_Next | H1: RF_1M/100 | I1: Front_Call_Delta | J1: Next_Call_Delta | K1: Call Delta（Trading） | L1: Put Delta (Trading) | M1: Straddle Delta | N1: Hedge
A2: 45659 | B2: 5868.55 | C2: 5870 | D2: 15 | E2: 50 | F2: 14.31 | G2: 14.373 | H2: 0.042912 | I2: =_xlfn.NORM.S.DIST((LN(B2/C2)+(H2+0.5*(F2/100)^2)*(D2/365))/((F2/100)*SQRT(D2/365)),TRUE) -> 0.52662133 | J2: =_xlfn.NORM.S.DIST((LN(B2/C2)+(H2+0.5*(G2/100)^2)*(E2/365))/((G2/100)*SQRT(E2/365)),TRUE) -> 0.55268831 | K2: =IF(ABS(D2-30)<ABS(E2-30), I2, J2) -> 0.52662133 | L2: =K2-1 -> -0.47337867 | M2: =K2+L2 -> 0.053242669 | N2: =-M2 -> -0.053242669
A3: 45660 | B3: 5942.47 | C3: 5940 | D3: 14 | E3: 49 | F3: 12.103 | G3: 13.127 | H3: 0.042626 | I3: =_xlfn.NORM.S.DIST((LN(B3/C3)+(H3+0.5*(F3/100)^2)*(D3/365))/((F3/100)*SQRT(D3/365)),TRUE) -> 0.53917959 | J3: =_xlfn.NORM.S.DIST((LN(B3/C3)+(H3+0.5*(G3/100)^2)*(E3/365))/((G3/100)*SQRT(E3/365)),TRUE) -> 0.56027583 | K3: =IF(ABS(D3-30)<ABS(E3-30), I3, J3) -> 0.53917959 | L3: =K3-1 -> -0.46082041 | M3: =K3+L3 -> 0.078359179 | N3: =-M3 -> -0.078359179
A4: 45663 | B4: 5975.38 | C4: 5975 | D4: 11 | E4: 46 | F4: 12.246 | G4: 12.896 | H4: 0.043106 | I4: =_xlfn.NORM.S.DIST((LN(B4/C4)+(H4+0.5*(F4/100)^2)*(D4/365))/((F4/100)*SQRT(D4/365)),TRUE) -> 0.52978458 | J4: =_xlfn.NORM.S.DIST((LN(B4/C4)+(H4+0.5*(G4/100)^2)*(E4/365))/((G4/100)*SQRT(E4/365)),TRUE) -> 0.55683229 | K4: =IF(ABS(D4-30)<ABS(E4-30), I4, J4) -> 0.55683229 | L4: =K4-1 -> -0.44316771 | M4: =K4+L4 -> 0.11366458 | N4: =-M4 -> -0.11366458
A5: 45664 | B5: 5909.03 | C5: 5910 | D5: 10 | E5: 45 | F5: 14.436 | G5: 14.319 | H5: 0.043024 | I5: =_xlfn.NORM.S.DIST((LN(B5/C5)+(H5+0.5*(F5/100)^2)*(D5/365))/((F5/100)*SQRT(D5/365)),TRUE) -> 0.5216952 | J5: =_xlfn.NORM.S.DIST((LN(B5/C5)+(H5+0.5*(G5/100)^2)*(E5/365))/((G5/100)*SQRT(E5/365)),TRUE) -> 0.55067831 | K5: =IF(ABS(D5-30)<ABS(E5-30), I5, J5) -> 0.55067831 | L5: =K5-1 -> -0.44932169 | M5: =K5+L5 -> 0.10135662 | N5: =-M5 -> -0.10135662
A6: 45665 | B6: 5918.25 | C6: 5920 | D6: 9 | E6: 44 | F6: 14.503 | G6: 14.171 | H6: 0.042942 | I6: =_xlfn.NORM.S.DIST((LN(B6/C6)+(H6+0.5*(F6/100)^2)*(D6/365))/((F6/100)*SQRT(D6/365)),TRUE) -> 0.51790605 | J6: =_xlfn.NORM.S.DIST((LN(B6/C6)+(H6+0.5*(G6/100)^2)*(E6/365))/((G6/100)*SQRT(E6/365)),TRUE) -> 0.54926438 | K6: =IF(ABS(D6-30)<ABS(E6-30), I6, J6) -> 0.54926438 | L6: =K6-1 -> -0.45073562 | M6: =K6+L6 -> 0.098528762 | N6: =-M6 -> -0.098528762
A7: 45667 | B7: 5827.04 | C7: 5825 | D7: 7 | E7: 42 | F7: 16.298 | G7: 15.64 | H7: 0.04283 | I7: =_xlfn.NORM.S.DIST((LN(B7/C7)+(H7+0.5*(F7/100)^2)*(D7/365))/((F7/100)*SQRT(D7/365)),TRUE) -> 0.52519316 | J7: =_xlfn.NORM.S.DIST((LN(B7/C7)+(H7+0.5*(G7/100)^2)*(E7/365))/((G7/100)*SQRT(E7/365)),TRUE) -> 0.55014243 | K7: =IF(ABS(D7-30)<ABS(E7-30), I7, J7) -> 0.55014243 | L7: =K7-1 -> -0.44985757 | M7: =K7+L7 -> 0.10028485 | N7: =-M7 -> -0.10028485
A8: 45670 | B8: 5836.22 | C8: 5835 | D8: 4 | E8: 39 | F8: 16.767 | G8: 15.195 | H8: 0.043055 | I8: =_xlfn.NORM.S.DIST((LN(B8/C8)+(H8+0.5*(F8/100)^2)*(D8/365))/((F8/100)*SQRT(D8/365)),TRUE) -> 0.51896984 | J8: =_xlfn.NORM.S.DIST((LN(B8/C8)+(H8+0.5*(G8/100)^2)*(E8/365))/((G8/100)*SQRT(E8/365)),TRUE) -> 0.54841763 | K8: =IF(ABS(D8-30)<ABS(E8-30), I8, J8) -> 0.54841763 | L8: =K8-1 -> -0.45158237 | M8: =K8+L8 -> 0.096835266 | N8: =-M8 -> -0.096835266
